Workbook

Sheet Recommendations
A1: ACASM – Recommendations for Use (Minnesota County & Statewide)
A3: Recommendations
A5: ACASM – Recommendations for Use (Minnesota County & Statewide)
A7: 1) Use ACASM for workforce planning, not performance grading
A8: - ACASM estimates staffing need based on workload/complexity/capacity. It should not be used to “rank”
A9: counties for compliance or staff performance.
A11: 2) Establish a stable baseline period (per county)
A12: - Choose a baseline quarter (or annual baseline) with stable operations (no major system outages, mass
A13: vacancies, or extraordinary policy shocks).
A14: - Refresh baseline annually (or semi-annually) to prevent drift.
A16: 3) Standardize workload categories and weights statewide
A17: - Start with the provided weights as “Version 1”.
... A49: - Include a short narrative on what is driving changes (arrivals vs complexity vs baseline productivity).

Sheet Data_Dictionary
A1: ACASM – Data Dictionary (Minnesota County & Statewide)
A3: Definitions
A5: ACASM – Data Dictionary (Minnesota County & Statewide)
A7: A) Core Concepts
A8: - AP (Arrival Points): Standardized workload points created from incoming work items during the period.
A9: - W̄ (Average Case Weight): Average complexity-adjusted weight across cases.
A10: - CPF (Complexity Pressure Factor): Ratio of current W̄ to baseline W̄.
A11: - P_ref (Baseline Productivity): Completed workload points per FTE during the baseline period.
A12: - P_eff (Effective Productivity): P_ref adjusted downward/upward by CPF.
A13: - Capacity_eff: Effective capacity in points = FTE_on * P_eff.
A14: - Utilization (U): Demand-to-capacity ratio = AP / Capacity_eff.
A15: - Backlog_End: Backlog_Start + AP - Capacity_eff.
... A81: - One row per county/period with key measures for Tableau/Power BI/Streamlit.

Sheet Weights
A1: Category | B1: Default_Weight
A2: Customer Contacts - Email/Portal | B2: 0.15
A3: Customer Contacts - Telephone | B3: 0.2
A4: Enforcement / R&M Actions | B4: 1.3
A5: Full Locate / Long Locate | B5: 2
A6: Incarceration Coordination | B6: 0.5
A7: Interpreter/Language Services | B7: 0.6
A8: METS / Interstate Complexity | B8: 1.5
A9: Safety / High Risk Handling | B9: 0.7
A10: Standard Case Work | B10: 1
A11: Unlocatable / Skip Work | B11: 0.8

Sheet County_List
A1: County | B1: Region (optional) | C1: Notes (optional)
A2: Aitkin
A3: Anoka
A4: Becker
A5: Beltrami
A6: Benton
A7: Big Stone
A8: Blue Earth
A9: Brown
A10: Carlton
A11: Carver
A12: Cass
A13: Chippewa
... A87: Yellow Medicine

Sheet Inputs_State
A1: Period | B1: 2025 Q4
A2: Delta per Complexity Factor (Δ) | B2: 0.062
A3: Utilization Green Max | B3: 0.75
A4: Utilization Amber Max | B4: 0.85
A5: Default Buffer (FTE) | B5: 0.30
A6: State Notes | B6: Edit county-level inputs on County_Baseline
A8: Demo Mode (TRUE/FALSE) | B8: TRUE
A9: Demo Note | B9: Synthetic demo data prefilled for training/walkthrough; overwrite with real data when available.

Sheet County_Baseline
A1: County | B1: Period | C1: FTE_on | D1: Buffer_FTE | E1: Backlog_Start | F1: Completed_Points_Baseline | G1: Avg_FTE_Baseline | H1: Wbar_Baseline
A2: Aitkin | B2: =Inputs_State!$B$1 | C2: 11 | D2: 0.3 | E2: 2977 | F2: 9472 | G2: 9.9 | H2: 1.648
A3: Anoka | B3: =Inputs_State!$B$1 | C3: 66.2 | D3: 0.5 | E3: 13382 | F3: 53528 | G3: 64.3 | H3: 1.71
A4: Becker | B4: =Inputs_State!$B$1 | C4: 4.3 | D4: 0.3 | E4: 1014 | F4: 3748 | G4: 4.5 | H4: 1.685
A5: Beltrami | B5: =Inputs_State!$B$1 | C5: 31.2 | D5: 0.4 | E5: 1940 | F5: 27573 | G5: 32 | H5: 1.716
A6: Benton | B6: =Inputs_State!$B$1 | C6: 14.5 | D6: 0.3 | E6: 3502 | F6: 12686 | G6: 12.9 | H6: 1.629
A7: Big Stone | B7: =Inputs_State!$B$1 | C7: 12.9 | D7: 0.3 | E7: 2849 | F7: 12889 | G7: 14.8 | H7: 1.674
A8: Blue Earth | B8: =Inputs_State!$B$1 | C8: 31.6 | D8: 0.4 | E8: 579 | F8: 30276 | G8: 31.9 | H8: 1.72
A9: Brown | B9: =Inputs_State!$B$1 | C9: 6.5 | D9: 0.3 | E9: 723 | F9: 4343 | G9: 5.4 | H9: 1.628
A10: Carlton | B10: =Inputs_State!$B$1 | C10: 11 | D10: 0.3 | E10: 4121 | F10: 8272 | G10: 9.8 | H10: 1.657
A11: Carver | B11: =Inputs_State!$B$1 | C11: 57.7 | D11: 0.5 | E11: 8758 | F11: 48006 | G11: 58.6 | H11: 1.692
A12: Cass | B12: =Inputs_State!$B$1 | C12: 14.9 | D12: 0.3 | E12: 4625 | F12: 15324 | G12: 15.6 | H12: 1.676
A13: Chippewa | B13: =Inputs_State!$B$1 | C13: 6.5 | D13: 0.3 | E13: 2452 | F13: 4652 | G13: 5.6 | H13: 1.652
... A87: Yellow Medicine | B87: =Inputs_State!$B$1 | C87: 6.3 | D87: 0.3 | E87: 2096 | F87: 5571 | G87: 5.8 | H87: 1.696

Sheet County_Arrivals
A1: County | B1: Period | C1: Category | D1: Count | E1: Weight | F1: Points
A2: Aitkin | B2: =Inputs_State!$B$1 | C2: Standard Case Work | D2: 241 | E2: =IFERROR(VLOOKUP(C2,Weights!$A$2:$B$11,2,FALSE),1) | F2: =D2*E2
A3: Aitkin | B3: =Inputs_State!$B$1 | C3: Full Locate / Long Locate | D3: 424 | E3: =IFERROR(VLOOKUP(C3,Weights!$A$2:$B$11,2,FALSE),2) | F3: =D3*E3
A4: Aitkin | B4: =Inputs_State!$B$1 | C4: METS / Interstate Complexity | D4: 111 | E4: =IFERROR(VLOOKUP(C4,Weights!$A$2:$B$11,2,FALSE),1.5) | F4: =D4*E4
A5: Aitkin | B5: =Inputs_State!$B$1 | C5: Enforcement / R&M Actions | D5: 400 | E5: =IFERROR(VLOOKUP(C5,Weights!$A$2:$B$11,2,FALSE),1.3) | F5: =D5*E5
A6: Aitkin | B6: =Inputs_State!$B$1 | C6: Customer Contacts - Telephone | D6: 1987 | E6: =IFERROR(VLOOKUP(C6,Weights!$A$2:$B$11,2,FALSE),0.2) | F6: =D6*E6
A7: Aitkin | B7: =Inputs_State!$B$1 | C7: Customer Contacts - Email/Portal | D7: 15322 | E7: =IFERROR(VLOOKUP(C7,Weights!$A$2:$B$11,2,FALSE),0.15) | F7: =D7*E7
A8: Aitkin | B8: =Inputs_State!$B$1 | C8: Interpreter/Language Services | D8: 1113 | E8: =IFERROR(VLOOKUP(C8,Weights!$A$2:$B$11,2,FALSE),0.6) | F8: =D8*E8
A9: Aitkin | B9: =Inputs_State!$B$1 | C9: Safety / High Risk Handling | D9: 215 | E9: =IFERROR(VLOOKUP(C9,Weights!$A$2:$B$11,2,FALSE),0.7) | F9: =D9*E9
A10: Aitkin | B10: =Inputs_State!$B$1 | C10: Incarceration Coordination | D10: 4175 | E10: =IFERROR(VLOOKUP(C10,Weights!$A$2:$B$11,2,FALSE),0.5) | F10: =D10*E10
A11: Aitkin | B11: =Inputs_State!$B$1 | C11: Unlocatable / Skip Work | D11: 284 | E11: =IFERROR(VLOOKUP(C11,Weights!$A$2:$B$11,2,FALSE),0.8) | F11: =D11*E11
A12: Anoka | B12: =Inputs_State!$B$1 | C12: Standard Case Work | D12: 1517 | E12: =IFERROR(VLOOKUP(C12,Weights!$A$2:$B$11,2,FALSE),1) | F12: =D12*E12
A13: Anoka | B13: =Inputs_State!$B$1 | C13: Full Locate / Long Locate | D13: 2095 | E13: =IFERROR(VLOOKUP(C13,Weights!$A$2:$B$11,2,FALSE),2) | F13: =D13*E13
A14: Anoka | B14: =Inputs_State!$B$1 | C14: METS / Interstate Complexity | D14: 682 | E14: =IFERROR(VLOOKUP(C14,Weights!$A$2:$B$11,2,FALSE),1.5) | F14: =D14*E14
A15: Anoka | B15: =Inputs_State!$B$1 | C15: Enforcement / R&M Actions | D15: 2397 | E15: =IFERROR(VLOOKUP(C15,Weights!$A$2:$B$11,2,FALSE),1.3) | F15: =D15*E15
A16: Anoka | B16: =Inputs_State!$B$1 | C16: Customer Contacts - Telephone | D16: 14986 | E16: =IFERROR(VLOOKUP(C16,Weights!$A$2:$B$11,2,FALSE),0.2) | F16: =D16*E16
A17: Anoka | B17: =Inputs_State!$B$1 | C17: Customer Contacts - Email/Portal | D17: 84617 | E17: =IFERROR(VLOOKUP(C17,Weights!$A$2:$B$11,2,FALSE),0.15) | F17: =D17*E17
A18: Anoka | B18: =Inputs_State!$B$1 | C18: Interpreter/Language Services | D18: 7301 | E18: =IFERROR(VLOOKUP(C18,Weights!$A$2:$B$11,2,FALSE),0.6) | F18: =D18*E18
A19: Anoka | B19: =Inputs_State!$B$1 | C19: Safety / High Risk Handling | D19: 1300 | E19: =IFERROR(VLOOKUP(C19,Weights!$A$2:$B$11,2,FALSE),0.7) | F19: =D19*E19
A20: Anoka | B20: =Inputs_State!$B$1 | C20: Incarceration Coordination | D20: 25812 | E20: =IFERROR(VLOOKUP(C20,Weights!$A$2:$B$11,2,FALSE),0.5) | F20: =D20*E20
A21: Anoka | B21: =Inputs_State!$B$1 | C21: Unlocatable / Skip Work | D21: 1888 | E21: =IFERROR(VLOOKUP(C21,Weights!$A$2:$B$11,2,FALSE),0.8) | F21: =D21*E21
A22: Becker | B22: =Inputs_State!$B$1 | C22: Standard Case Work | D22: 91 | E22: =IFERROR(VLOOKUP(C22,Weights!$A$2:$B$11,2,FALSE),1) | F22: =D22*E22
A23: Becker | B23: =Inputs_State!$B$1 | C23: Full Locate / Long Locate | D23: 167 | E23: =IFERROR(VLOOKUP(C23,Weights!$A$2:$B$11,2,FALSE),2) | F23: =D23*E23
A24: Becker | B24: =Inputs_State!$B$1 | C24: METS / Interstate Complexity | D24: 37 | E24: =IFERROR(VLOOKUP(C24,Weights!$A$2:$B$11,2,FALSE),1.5) | F24: =D24*E24
A25: Becker | B25: =Inputs_State!$B$1 | C25: Enforcement / R&M Actions | D25: 133 | E25: =IFERROR(VLOOKUP(C25,Weights!$A$2:$B$11,2,FALSE),1.3) | F25: =D25*E25
A26: Becker | B26: =Inputs_State!$B$1 | C26: Customer Contacts - Telephone | D26: 962 | E26: =IFERROR(VLOOKUP(C26,Weights!$A$2:$B$11,2,FALSE),0.2) | F26: =D26*E26
A27: Becker | B27: =Inputs_State!$B$1 | C27: Customer Contacts - Email/Portal | D27: 5501 | E27: =IFERROR(VLOOKUP(C27,Weights!$A$2:$B$11,2,FALSE),0.15) | F27: =D27*E27
A28: Becker | B28: =Inputs_State!$B$1 | C28: Interpreter/Language Services | D28: 539 | E28: =IFERROR(VLOOKUP(C28,Weights!$A$2:$B$11,2,FALSE),0.6) | F28: =D28*E28
A29: Becker | B29: =Inputs_State!$B$1 | C29: Safety / High Risk Handling | D29: 79 | E29: =IFERROR(VLOOKUP(C29,Weights!$A$2:$B$11,2,FALSE),0.7) | F29: =D29*E29
A30: Becker | B30: =Inputs_State!$B$1 | C30: Incarceration Coordination | D30: 1655 | E30: =IFERROR(VLOOKUP(C30,Weights!$A$2:$B$11,2,FALSE),0.5) | F30: =D30*E30
A31: Becker | B31: =Inputs_State!$B$1 | C31: Unlocatable / Skip Work | D31: 127 | E31: =IFERROR(VLOOKUP(C31,Weights!$A$2:$B$11,2,FALSE),0.8) | F31: =D31*E31
A32: Beltrami | B32: =Inputs_State!$B$1 | C32: Standard Case Work | D32: 582 | E32: =IFERROR(VLOOKUP(C32,Weights!$A$2:$B$11,2,FALSE),1) | F32: =D32*E32
A33: Beltrami | B33: =Inputs_State!$B$1 | C33: Full Locate / Long Locate | D33: 1020 | E33: =IFERROR(VLOOKUP(C33,Weights!$A$2:$B$11,2,FALSE),2) | F33: =D33*E33
A34: Beltrami | B34: =Inputs_State!$B$1 | C34: METS / Interstate Complexity | D34: 281 | E34: =IFERROR(VLOOKUP(C34,Weights!$A$2:$B$11,2,FALSE),1.5) | F34: =D34*E34
A35: Beltrami | B35: =Inputs_State!$B$1 | C35: Enforcement / R&M Actions | D35: 999 | E35: =IFERROR(VLOOKUP(C35,Weights!$A$2:$B$11,2,FALSE),1.3) | F35: =D35*E35
A36: Beltrami | B36: =Inputs_State!$B$1 | C36: Customer Contacts - Telephone | D36: 5742 | E36: =IFERROR(VLOOKUP(C36,Weights!$A$2:$B$11,2,FALSE),0.2) | F36: =D36*E36
A37: Beltrami | B37: =Inputs_State!$B$1 | C37: Customer Contacts - Email/Portal | D37: 42656 | E37: =IFERROR(VLOOKUP(C37,Weights!$A$2:$B$11,2,FALSE),0.15) | F37: =D37*E37
A38: Beltrami | B38: =Inputs_State!$B$1 | C38: Interpreter/Language Services | D38: 3612 | E38: =IFERROR(VLOOKUP(C38,Weights!$A$2:$B$11,2,FALSE),0.6) | F38: =D38*E38
A39: Beltrami | B39: =Inputs_State!$B$1 | C39: Safety / High Risk Handling | D39: 579 | E39: =IFERROR(VLOOKUP(C39,Weights!$A$2:$B$11,2,FALSE),0.7) | F39: =D39*E39
A40: Beltrami | B40: =Inputs_State!$B$1 | C40: Incarceration Coordination | D40: 12167 | E40: =IFERROR(VLOOKUP(C40,Weights!$A$2:$B$11,2,FALSE),0.5) | F40: =D40*E40
...

Sheet County_Complexity
A1: County | B1: Period | C1: m_bucket | D1: Cases_Current | E1: Cases_Baseline | F1: Weight_Current | G1: Weight_Baseline
A2: Aitkin | B2: =Inputs_State!$B$1 | C2: 0 | D2: 1350 | E2: 1376 | F2: =D2*(1+Inputs_State!$B$2*0) | G2: =E2*(1+Inputs_State!$B$2*0)
A3: Aitkin | B3: =Inputs_State!$B$1 | C3: 1 | D3: 2720 | E3: 2865 | F3: =D3*(1+Inputs_State!$B$2*1) | G3: =E3*(1+Inputs_State!$B$2*1)
A4: Aitkin | B4: =Inputs_State!$B$1 | C4: 2 | D4: 3547 | E4: 3703 | F4: =D4*(1+Inputs_State!$B$2*2) | G4: =E4*(1+Inputs_State!$B$2*2)
A5: Aitkin | B5: =Inputs_State!$B$1 | C5: 3 | D5: 3425 | E5: 3439 | F5: =D5*(1+Inputs_State!$B$2*3) | G5: =E5*(1+Inputs_State!$B$2*3)
A6: Aitkin | B6: =Inputs_State!$B$1 | C6: 4 | D6: 2759 | E6: 2859 | F6: =D6*(1+Inputs_State!$B$2*4) | G6: =E6*(1+Inputs_State!$B$2*4)
A7: Aitkin | B7: =Inputs_State!$B$1 | C7: 5 | D7: 1990 | E7: 2189 | F7: =D7*(1+Inputs_State!$B$2*5) | G7: =E7*(1+Inputs_State!$B$2*5)
A8: Aitkin | B8: =Inputs_State!$B$1 | C8: 6+ | D8: 1164 | E8: 1189 | F8: =D8*(1+Inputs_State!$B$2*6) | G8: =E8*(1+Inputs_State!$B$2*6)
A9: Anoka | B9: =Inputs_State!$B$1 | C9: 0 | D9: 10735 | E9: 9663 | F9: =D9*(1+Inputs_State!$B$2*0) | G9: =E9*(1+Inputs_State!$B$2*0)
A10: Anoka | B10: =Inputs_State!$B$1 | C10: 1 | D10: 21463 | E10: 19338 | F10: =D10*(1+Inputs_State!$B$2*1) | G10: =E10*(1+Inputs_State!$B$2*1)
A11: Anoka | B11: =Inputs_State!$B$1 | C11: 2 | D11: 27852 | E11: 25707 | F11: =D11*(1+Inputs_State!$B$2*2) | G11: =E11*(1+Inputs_State!$B$2*2)
A12: Anoka | B12: =Inputs_State!$B$1 | C12: 3 | D12: 26418 | E12: 24367 | F12: =D12*(1+Inputs_State!$B$2*3) | G12: =E12*(1+Inputs_State!$B$2*3)
A13: Anoka | B13: =Inputs_State!$B$1 | C13: 4 | D13: 21366 | E13: 19087 | F13: =D13*(1+Inputs_State!$B$2*4) | G13: =E13*(1+Inputs_State!$B$2*4)
A14: Anoka | B14: =Inputs_State!$B$1 | C14: 5 | D14: 16147 | E14: 14746 | F14: =D14*(1+Inputs_State!$B$2*5) | G14: =E14*(1+Inputs_State!$B$2*5)
A15: Anoka | B15: =Inputs_State!$B$1 | C15: 6+ | D15: 9390 | E15: 8340 | F15: =D15*(1+Inputs_State!$B$2*6) | G15: =E15*(1+Inputs_State!$B$2*6)
A16: Becker | B16: =Inputs_State!$B$1 | C16: 0 | D16: 673 | E16: 689 | F16: =D16*(1+Inputs_State!$B$2*0) | G16: =E16*(1+Inputs_State!$B$2*0)
A17: Becker | B17: =Inputs_State!$B$1 | C17: 1 | D17: 1352 | E17: 1309 | F17: =D17*(1+Inputs_State!$B$2*1) | G17: =E17*(1+Inputs_State!$B$2*1)
A18: Becker | B18: =Inputs_State!$B$1 | C18: 2 | D18: 1822 | E18: 1723 | F18: =D18*(1+Inputs_State!$B$2*2) | G18: =E18*(1+Inputs_State!$B$2*2)
A19: Becker | B19: =Inputs_State!$B$1 | C19: 3 | D19: 1747 | E19: 1631 | F19: =D19*(1+Inputs_State!$B$2*3) | G19: =E19*(1+Inputs_State!$B$2*3)
A20: Becker | B20: =Inputs_State!$B$1 | C20: 4 | D20: 1485 | E20: 1343 | F20: =D20*(1+Inputs_State!$B$2*4) | G20: =E20*(1+Inputs_State!$B$2*4)
A21: Becker | B21: =Inputs_State!$B$1 | C21: 5 | D21: 1114 | E21: 992 | F21: =D21*(1+Inputs_State!$B$2*5) | G21: =E21*(1+Inputs_State!$B$2*5)
A22: Becker | B22: =Inputs_State!$B$1 | C22: 6+ | D22: 618 | E22: 569 | F22: =D22*(1+Inputs_State!$B$2*6) | G22: =E22*(1+Inputs_State!$B$2*6)
A23: Beltrami | B23: =Inputs_State!$B$1 | C23: 0 | D23: 5503 | E23: 5053 | F23: =D23*(1+Inputs_State!$B$2*0) | G23: =E23*(1+Inputs_State!$B$2*0)
A24: Beltrami | B24: =Inputs_State!$B$1 | C24: 1 | D24: 10903 | E24: 10066 | F24: =D24*(1+Inputs_State!$B$2*1) | G24: =E24*(1+Inputs_State!$B$2*1)
A25: Beltrami | B25: =Inputs_State!$B$1 | C25: 2 | D25: 14203 | E25: 13113 | F25: =D25*(1+Inputs_State!$B$2*2) | G25: =E25*(1+Inputs_State!$B$2*2)
A26: Beltrami | B26: =Inputs_State!$B$1 | C26: 3 | D26: 13682 | E26: 12527 | F26: =D26*(1+Inputs_State!$B$2*3) | G26: =E26*(1+Inputs_State!$B$2*3)
A27: Beltrami | B27: =Inputs_State!$B$1 | C27: 4 | D27: 11055 | E27: 9993 | F27: =D27*(1+Inputs_State!$B$2*4) | G27: =E27*(1+Inputs_State!$B$2*4)
A28: Beltrami | B28: =Inputs_State!$B$1 | C28: 5 | D28: 8195 | E28: 7486 | F28: =D28*(1+Inputs_State!$B$2*5) | G28: =E28*(1+Inputs_State!$B$2*5)
A29: Beltrami | B29: =Inputs_State!$B$1 | C29: 6+ | D29: 4743 | E29: 4268 | F29: =D29*(1+Inputs_State!$B$2*6) | G29: =E29*(1+Inputs_State!$B$2*6)
A30: Benton | B30: =Inputs_State!$B$1 | C30: 0 | D30: 1589 | E30: 1661 | F30: =D30*(1+Inputs_State!$B$2*0) | G30: =E30*(1+Inputs_State!$B$2*0)
A31: Benton | B31: =Inputs_State!$B$1 | C31: 1 | D31: 3143 | E31: 3307 | F31: =D31*(1+Inputs_State!$B$2*1) | G31: =E31*(1+Inputs_State!$B$2*1)
A32: Benton | B32: =Inputs_State!$B$1 | C32: 2 | D32: 4253 | E32: 4298 | F32: =D32*(1+Inputs_State!$B$2*2) | G32: =E32*(1+Inputs_State!$B$2*2)
A33: Benton | B33: =Inputs_State!$B$1 | C33: 3 | D33: 3979 | E33: 4048 | F33: =D33*(1+Inputs_State!$B$2*3) | G33: =E33*(1+Inputs_State!$B$2*3)
A34: Benton | B34: =Inputs_State!$B$1 | C34: 4 | D34: 3287 | E34: 3338 | F34: =D34*(1+Inputs_State!$B$2*4) | G34: =E34*(1+Inputs_State!$B$2*4)
A35: Benton | B35: =Inputs_State!$B$1 | C35: 5 | D35: 2355 | E35: 2432 | F35: =D35*(1+Inputs_State!$B$2*5) | G35: =E35*(1+Inputs_State!$B$2*5)
A36: Benton | B36: =Inputs_State!$B$1 | C36: 6+ | D36: 1373 | E36: 1452 | F36: =D36*(1+Inputs_State!$B$2*6) | G36: =E36*(1+Inputs_State!$B$2*6)
A37: Big Stone | B37: =Inputs_State!$B$1 | C37: 0 | D37: 2120 | E37: 1954 | F37: =D37*(1+Inputs_State!$B$2*0) | G37: =E37*(1+Inputs_State!$B$2*0)
A38: Big Stone | B38: =Inputs_State!$B$1 | C38: 1 | D38: 4087 | E38: 3843 | F38: =D38*(1+Inputs_State!$B$2*1) | G38: =E38*(1+Inputs_State!$B$2*1)
A39: Big Stone | B39: =Inputs_State!$B$1 | C39: 2 | D39: 5599 | E39: 5345 | F39: =D39*(1+Inputs_State!$B$2*2) | G39: =E39*(1+Inputs_State!$B$2*2)
A40: Big Stone | B40: =Inputs_State!$B$1 | C40: 3 | D40: 5118 | E40: 5070 | F40: =D40*(1+Inputs_State!$B$2*3) | G40: =E40*(1+Inputs_State!$B$2*3)
...

Sheet County_Calculator
A1: County | B1: Period | C1: AP | D1: Cases_Current | E1: WC_Current | F1: Wbar_Current | G1: Cases_Baseline | H1: WC_Baseline | I1: Wbar_Baseline | J1: CPF | K1: P_ref | L1: P_eff | M1: FTE_on | N1: Capacity_eff | O1: Utilization | P1: Backlog_Start | Q1: Backlog_End | R1: Buffer_FTE | S1: FTE_required | T1: Gap | U1: RAG
A2: Aitkin | B2: =Inputs_State!$B$1 | C2: =SUMIFS(tblArrivals[Points],tblArrivals[County],A2) | D2: =SUMIFS(tblComplexity[Cases_Current],tblComplexity[County],A2) | E2: =SUMIFS(tblComplexity[Weight_Current],tblComplexity[County],A2) | F2: =IF(D2>0,E2/D2,0) | G2: =SUMIFS(tblComplexity[Cases_Baseline],tblComplexity[County],A2) | H2: =SUMIFS(tblComplexity[Weight_Baseline],tblComplexity[County],A2) | I2: =IF(G2>0,H2/G2,0) | J2: =IF(I2>0,F2/I2,1) | K2: =IFERROR(VLOOKUP(A2,tblBaseline,6,FALSE)/VLOOKUP(A2,tblBaseline,7,FALSE),0) | L2: =IF(J2>0,K2/J2,0) | M2: =IFERROR(VLOOKUP(A2,tblBaseline,3,FALSE),0) | N2: =M2*L2 | O2: =IF(N2>0,C2/N2,0) | P2: =IFERROR(VLOOKUP(A2,tblBaseline,5,FALSE),0) | Q2: =P2+C2-N2 | R2: =IFERROR(VLOOKUP(A2,tblBaseline,4,FALSE),Inputs_State!$B$5) | S2: =IF(L2>0,C2/L2,0)+R2 | T2: =S2-M2 | U2: =IF(O2>=Inputs_State!$B$4,"RED",IF(O2>=Inputs_State!$B$3,"AMBER","GREEN"))
A3: Anoka | B3: =Inputs_State!$B$1 | C3: =SUMIFS(tblArrivals[Points],tblArrivals[County],A3) | D3: =SUMIFS(tblComplexity[Cases_Current],tblComplexity[County],A3) | E3: =SUMIFS(tblComplexity[Weight_Current],tblComplexity[County],A3) | F3: =IF(D3>0,E3/D3,0) | G3: =SUMIFS(tblComplexity[Cases_Baseline],tblComplexity[County],A3) | H3: =SUMIFS(tblComplexity[Weight_Baseline],tblComplexity[County],A3) | I3: =IF(G3>0,H3/G3,0) | J3: =IF(I3>0,F3/I3,1) | K3: =IFERROR(VLOOKUP(A3,tblBaseline,6,FALSE)/VLOOKUP(A3,tblBaseline,7,FALSE),0) | L3: =IF(J3>0,K3/J3,0) | M3: =IFERROR(VLOOKUP(A3,tblBaseline,3,FALSE),0) | N3: =M3*L3 | O3: =IF(N3>0,C3/N3,0) | P3: =IFERROR(VLOOKUP(A3,tblBaseline,5,FALSE),0) | Q3: =P3+C3-N3 | R3: =IFERROR(VLOOKUP(A3,tblBaseline,4,FALSE),Inputs_State!$B$5) | S3: =IF(L3>0,C3/L3,0)+R3 | T3: =S3-M3 | U3: =IF(O3>=Inputs_State!$B$4,"RED",IF(O3>=Inputs_State!$B$3,"AMBER","GREEN"))
A4: Becker | B4: =Inputs_State!$B$1 | C4: =SUMIFS(tblArrivals[Points],tblArrivals[County],A4) | D4: =SUMIFS(tblComplexity[Cases_Current],tblComplexity[County],A4) | E4: =SUMIFS(tblComplexity[Weight_Current],tblComplexity[County],A4) | F4: =IF(D4>0,E4/D4,0) | G4: =SUMIFS(tblComplexity[Cases_Baseline],tblComplexity[County],A4) | H4: =SUMIFS(tblComplexity[Weight_Baseline],tblComplexity[County],A4) | I4: =IF(G4>0,H4/G4,0) | J4: =IF(I4>0,F4/I4,1) | K4: =IFERROR(VLOOKUP(A4,tblBaseline,6,FALSE)/VLOOKUP(A4,tblBaseline,7,FALSE),0) | L4: =IF(J4>0,K4/J4,0) | M4: =IFERROR(VLOOKUP(A4,tblBaseline,3,FALSE),0) | N4: =M4*L4 | O4: =IF(N4>0,C4/N4,0) | P4: =IFERROR(VLOOKUP(A4,tblBaseline,5,FALSE),0) | Q4: =P4+C4-N4 | R4: =IFERROR(VLOOKUP(A4,tblBaseline,4,FALSE),Inputs_State!$B$5) | S4: =IF(L4>0,C4/L4,0)+R4 | T4: =S4-M4 | U4: =IF(O4>=Inputs_State!$B$4,"RED",IF(O4>=Inputs_State!$B$3,"AMBER","GREEN"))
A5: Beltrami | B5: =Inputs_State!$B$1 | C5: =SUMIFS(tblArrivals[Points],tblArrivals[County],A5) | D5: =SUMIFS(tblComplexity[Cases_Current],tblComplexity[County],A5) | E5: =SUMIFS(tblComplexity[Weight_Current],tblComplexity[County],A5) | F5: =IF(D5>0,E5/D5,0) | G5: =SUMIFS(tblComplexity[Cases_Baseline],tblComplexity[County],A5) | H5: =SUMIFS(tblComplexity[Weight_Baseline],tblComplexity[County],A5) | I5: =IF(G5>0,H5/G5,0) | J5: =IF(I5>0,F5/I5,1) | K5: =IFERROR(VLOOKUP(A5,tblBaseline,6,FALSE)/VLOOKUP(A5,tblBaseline,7,FALSE),0) | L5: =IF(J5>0,K5/J5,0) | M5: =IFERROR(VLOOKUP(A5,tblBaseline,3,FALSE),0) | N5: =M5*L5 | O5: =IF(N5>0,C5/N5,0) | P5: =IFERROR(VLOOKUP(A5,tblBaseline,5,FALSE),0) | Q5: =P5+C5-N5 | R5: =IFERROR(VLOOKUP(A5,tblBaseline,4,FALSE),Inputs_State!$B$5) | S5: =IF(L5>0,C5/L5,0)+R5 | T5: =S5-M5 | U5: =IF(O5>=Inputs_State!$B$4,"RED",IF(O5>=Inputs_State!$B$3,"AMBER","GREEN"))
A6: Benton | B6: =Inputs_State!$B$1 | C6: =SUMIFS(tblArrivals[Points],tblArrivals[County],A6) | D6: =SUMIFS(tblComplexity[Cases_Current],tblComplexity[County],A6) | E6: =SUMIFS(tblComplexity[Weight_Current],tblComplexity[County],A6) | F6: =IF(D6>0,E6/D6,0) | G6: =SUMIFS(tblComplexity[Cases_Baseline],tblComplexity[County],A6) | H6: =SUMIFS(tblComplexity[Weight_Baseline],tblComplexity[County],A6) | I6: =IF(G6>0,H6/G6,0) | J6: =IF(I6>0,F6/I6,1) | K6: =IFERROR(VLOOKUP(A6,tblBaseline,6,FALSE)/VLOOKUP(A6,tblBaseline,7,FALSE),0) | L6: =IF(J6>0,K6/J6,0) | M6: =IFERROR(VLOOKUP(A6,tblBaseline,3,FALSE),0) | N6: =M6*L6 | O6: =IF(N6>0,C6/N6,0) | P6: =IFERROR(VLOOKUP(A6,tblBaseline,5,FALSE),0) | Q6: =P6+C6-N6 | R6: =IFERROR(VLOOKUP(A6,tblBaseline,4,FALSE),Inputs_State!$B$5) | S6: =IF(L6>0,C6/L6,0)+R6 | T6: =S6-M6 | U6: =IF(O6>=Inputs_State!$B$4,"RED",IF(O6>=Inputs_State!$B$3,"AMBER","GREEN"))
A7: Big Stone | B7: =Inputs_State!$B$1 | C7: =SUMIFS(tblArrivals[Points],tblArrivals[County],A7) | D7: =SUMIFS(tblComplexity[Cases_Current],tblComplexity[County],A7) | E7: =SUMIFS(tblComplexity[Weight_Current],tblComplexity[County],A7) | F7: =IF(D7>0,E7/D7,0) | G7: =SUMIFS(tblComplexity[Cases_Baseline],tblComplexity[County],A7) | H7: =SUMIFS(tblComplexity[Weight_Baseline],tblComplexity[County],A7) | I7: =IF(G7>0,H7/G7,0) | J7: =IF(I7>0,F7/I7,1) | K7: =IFERROR(VLOOKUP(A7,tblBaseline,6,FALSE)/VLOOKUP(A7,tblBaseline,7,FALSE),0) | L7: =IF(J7>0,K7/J7,0) | M7: =IFERROR(VLOOKUP(A7,tblBaseline,3,FALSE),0) | N7: =M7*L7 | O7: =IF(N7>0,C7/N7,0) | P7: =IFERROR(VLOOKUP(A7,tblBaseline,5,FALSE),0) | Q7: =P7+C7-N7 | R7: =IFERROR(VLOOKUP(A7,tblBaseline,4,FALSE),Inputs_State!$B$5) | S7: =IF(L7>0,C7/L7,0)+R7 | T7: =S7-M7 | U7: =IF(O7>=Inputs_State!$B$4,"RED",IF(O7>=Inputs_State!$B$3,"AMBER","GREEN"))
A8: Blue Earth | B8: =Inputs_State!$B$1 | C8: =SUMIFS(tblArrivals[Points],tblArrivals[County],A8) | D8: =SUMIFS(tblComplexity[Cases_Current],tblComplexity[County],A8) | E8: =SUMIFS(tblComplexity[Weight_Current],tblComplexity[County],A8) | F8: =IF(D8>0,E8/D8,0) | G8: =SUMIFS(tblComplexity[Cases_Baseline],tblComplexity[County],A8) | H8: =SUMIFS(tblComplexity[Weight_Baseline],tblComplexity[County],A8) | I8: =IF(G8>0,H8/G8,0) | J8: =IF(I8>0,F8/I8,1) | K8: =IFERROR(VLOOKUP(A8,tblBaseline,6,FALSE)/VLOOKUP(A8,tblBaseline,7,FALSE),0) | L8: =IF(J8>0,K8/J8,0) | M8: =IFERROR(VLOOKUP(A8,tblBaseline,3,FALSE),0) | N8: =M8*L8 | O8: =IF(N8>0,C8/N8,0) | P8: =IFERROR(VLOOKUP(A8,tblBaseline,5,FALSE),0) | Q8: =P8+C8-N8 | R8: =IFERROR(VLOOKUP(A8,tblBaseline,4,FALSE),Inputs_State!$B$5) | S8: =IF(L8>0,C8/L8,0)+R8 | T8: =S8-M8 | U8: =IF(O8>=Inputs_State!$B$4,"RED",IF(O8>=Inputs_State!$B$3,"AMBER","GREEN"))
A9: Brown | B9: =Inputs_State!$B$1 | C9: =SUMIFS(tblArrivals[Points],tblArrivals[County],A9) | D9: =SUMIFS(tblComplexity[Cases_Current],tblComplexity[County],A9) | E9: =SUMIFS(tblComplexity[Weight_Current],tblComplexity[County],A9) | F9: =IF(D9>0,E9/D9,0) | G9: =SUMIFS(tblComplexity[Cases_Baseline],tblComplexity[County],A9) | H9: =SUMIFS(tblComplexity[Weight_Baseline],tblComplexity[County],A9) | I9: =IF(G9>0,H9/G9,0) | J9: =IF(I9>0,F9/I9,1) | K9: =IFERROR(VLOOKUP(A9,tblBaseline,6,FALSE)/VLOOKUP(A9,tblBaseline,7,FALSE),0) | L9: =IF(J9>0,K9/J9,0) | M9: =IFERROR(VLOOKUP(A9,tblBaseline,3,FALSE),0) | N9: =M9*L9 | O9: =IF(N9>0,C9/N9,0) | P9: =IFERROR(VLOOKUP(A9,tblBaseline,5,FALSE),0) | Q9: =P9+C9-N9 | R9: =IFERROR(VLOOKUP(A9,tblBaseline,4,FALSE),Inputs_State!$B$5) | S9: =IF(L9>0,C9/L9,0)+R9 | T9: =S9-M9 | U9: =IF(O9>=Inputs_State!$B$4,"RED",IF(O9>=Inputs_State!$B$3,"AMBER","GREEN"))
A10: Carlton | B10: =Inputs_State!$B$1 | C10: =SUMIFS(tblArrivals[Points],tblArrivals[County],A10) | D10: =SUMIFS(tblComplexity[Cases_Current],tblComplexity[County],A10) | E10: =SUMIFS(tblComplexity[Weight_Current],tblComplexity[County],A10) | F10: =IF(D10>0,E10/D10,0) | G10: =SUMIFS(tblComplexity[Cases_Baseline],tblComplexity[County],A10) | H10: =SUMIFS(tblComplexity[Weight_Baseline],tblComplexity[County],A10) | I10: =IF(G10>0,H10/G10,0) | J10: =IF(I10>0,F10/I10,1) | K10: =IFERROR(VLOOKUP(A10,tblBaseline,6,FALSE)/VLOOKUP(A10,tblBaseline,7,FALSE),0) | L10: =IF(J10>0,K10/J10,0) | M10: =IFERROR(VLOOKUP(A10,tblBaseline,3,FALSE),0) | N10: =M10*L10 | O10: =IF(N10>0,C10/N10,0) | P10: =IFERROR(VLOOKUP(A10,tblBaseline,5,FALSE),0) | Q10: =P10+C10-N10 | R10: =IFERROR(VLOOKUP(A10,tblBaseline,4,FALSE),Inputs_State!$B$5) | S10: =IF(L10>0,C10/L10,0)+R10 | T10: =S10-M10 | U10: =IF(O10>=Inputs_State!$B$4,"RED",IF(O10>=Inputs_State!$B$3,"AMBER","GREEN"))
A11: Carver | B11: =Inputs_State!$B$1 | C11: =SUMIFS(tblArrivals[Points],tblArrivals[County],A11) | D11: =SUMIFS(tblComplexity[Cases_Current],tblComplexity[County],A11) | E11: =SUMIFS(tblComplexity[Weight_Current],tblComplexity[County],A11) | F11: =IF(D11>0,E11/D11,0) | G11: =SUMIFS(tblComplexity[Cases_Baseline],tblComplexity[County],A11) | H11: =SUMIFS(tblComplexity[Weight_Baseline],tblComplexity[County],A11) | I11: =IF(G11>0,H11/G11,0) | J11: =IF(I11>0,F11/I11,1) | K11: =IFERROR(VLOOKUP(A11,tblBaseline,6,FALSE)/VLOOKUP(A11,tblBaseline,7,FALSE),0) | L11: =IF(J11>0,K11/J11,0) | M11: =IFERROR(VLOOKUP(A11,tblBaseline,3,FALSE),0) | N11: =M11*L11 | O11: =IF(N11>0,C11/N11,0) | P11: =IFERROR(VLOOKUP(A11,tblBaseline,5,FALSE),0) | Q11: =P11+C11-N11 | R11: =IFERROR(VLOOKUP(A11,tblBaseline,4,FALSE),Inputs_State!$B$5) | S11: =IF(L11>0,C11/L11,0)+R11 | T11: =S11-M11 | U11: =IF(O11>=Inputs_State!$B$4,"RED",IF(O11>=Inputs_State!$B$3,"AMBER","GREEN"))
A12: Cass | B12: =Inputs_State!$B$1 | C12: =SUMIFS(tblArrivals[Points],tblArrivals[County],A12) | D12: =SUMIFS(tblComplexity[Cases_Current],tblComplexity[County],A12) | E12: =SUMIFS(tblComplexity[Weight_Current],tblComplexity[County],A12) | F12: =IF(D12>0,E12/D12,0) | G12: =SUMIFS(tblComplexity[Cases_Baseline],tblComplexity[County],A12) | H12: =SUMIFS(tblComplexity[Weight_Baseline],tblComplexity[County],A12) | I12: =IF(G12>0,H12/G12,0) | J12: =IF(I12>0,F12/I12,1) | K12: =IFERROR(VLOOKUP(A12,tblBaseline,6,FALSE)/VLOOKUP(A12,tblBaseline,7,FALSE),0) | L12: =IF(J12>0,K12/J12,0) | M12: =IFERROR(VLOOKUP(A12,tblBaseline,3,FALSE),0) | N12: =M12*L12 | O12: =IF(N12>0,C12/N12,0) | P12: =IFERROR(VLOOKUP(A12,tblBaseline,5,FALSE),0) | Q12: =P12+C12-N12 | R12: =IFERROR(VLOOKUP(A12,tblBaseline,4,FALSE),Inputs_State!$B$5) | S12: =IF(L12>0,C12/L12,0)+R12 | T12: =S12-M12 | U12: =IF(O12>=Inputs_State!$B$4,"RED",IF(O12>=Inputs_State!$B$3,"AMBER","GREEN"))
A13: Chippewa | B13: =Inputs_State!$B$1 | C13: =SUMIFS(tblArrivals[Points],tblArrivals[County],A13) | D13: =SUMIFS(tblComplexity[Cases_Current],tblComplexity[County],A13) | E13: =SUMIFS(tblComplexity[Weight_Current],tblComplexity[County],A13) | F13: =IF(D13>0,E13/D13,0) | G13: =SUMIFS(tblComplexity[Cases_Baseline],tblComplexity[County],A13) | H13: =SUMIFS(tblComplexity[Weight_Baseline],tblComplexity[County],A13) | I13: =IF(G13>0,H13/G13,0) | J13: =IF(I13>0,F13/I13,1) | K13: =IFERROR(VLOOKUP(A13,tblBaseline,6,FALSE)/VLOOKUP(A13,tblBaseline,7,FALSE),0) | L13: =IF(J13>0,K13/J13,0) | M13: =IFERROR(VLOOKUP(A13,tblBaseline,3,FALSE),0) | N13: =M13*L13 | O13: =IF(N13>0,C13/N13,0) | P13: =IFERROR(VLOOKUP(A13,tblBaseline,5,FALSE),0) | Q13: =P13+C13-N13 | R13: =IFERROR(VLOOKUP(A13,tblBaseline,4,FALSE),Inputs_State!$B$5) | S13: =IF(L13>0,C13/L13,0)+R13 | T13: =S13-M13 | U13: =IF(O13>=Inputs_State!$B$4,"RED",IF(O13>=Inputs_State!$B$3,"AMBER","GREEN"))
... A87: Yellow Medicine | B87: =Inputs_State!$B$1 | C87: =SUMIFS(tblArrivals[Points],tblArrivals[County],A87) | D87: =SUMIFS(tblComplexity[Cases_Current],tblComplexity[County],A87) | E87: =SUMIFS(tblComplexity[Weight_Current],tblComplexity[County],A87) | F87: =IF(D87>0,E87/D87,0) | G87: =SUMIFS(tblComplexity[Cases_Baseline],tblComplexity[County],A87) | H87: =SUMIFS(tblComplexity[Weight_Baseline],tblComplexity[County],A87) | I87: =IF(G87>0,H87/G87,0) | J87: =IF(I87>0,F87/I87,1) | K87: =IFERROR(VLOOKUP(A87,tblBaseline,6,FALSE)/VLOOKUP(A87,tblBaseline,7,FALSE),0) | L87: =IF(J87>0,K87/J87,0) | M87: =IFERROR(VLOOKUP(A87,tblBaseline,3,FALSE),0) | N87: =M87*L87 | O87: =IF(N87>0,C87/N87,0) | P87: =IFERROR(VLOOKUP(A87,tblBaseline,5,FALSE),0) | Q87: =P87+C87-N87 | R87: =IFERROR(VLOOKUP(A87,tblBaseline,4,FALSE),Inputs_State!$B$5) | S87: =IF(L87>0,C87/L87,0)+R87 | T87: =S87-M87 | U87: =IF(O87>=Inputs_State!$B$4,"RED",IF(O87>=Inputs_State!$B$3,"AMBER","GREEN"))

Sheet State_Rollup
A1: Minnesota ACASM v1 — Statewide Rollup
A3: Period | B3: =Inputs_State!$B$1
A4: State Arrival Points (AP_state) | B4: =SUM(tblCountyCalc[AP])
A5: State Effective Capacity (Σ FTE_on * P_eff) | B5: =SUM(tblCountyCalc[Capacity_eff])
A6: State Utilization (AP_state / Cap_state) | B6: =IF(B5>0,B4/B5,0)
A7: State Backlog Start (Σ county) | B7: =SUM(tblCountyCalc[Backlog_Start])
A8: State Backlog End (Σ county) | B8: =SUM(tblCountyCalc[Backlog_End])
A9: State FTE Required (Σ county) | B9: =SUM(tblCountyCalc[FTE_required])
A10: State FTE On (Σ county) | B10: =SUM(tblCountyCalc[FTE_on])
A11: State Staffing Gap (Σ county) | B11: =SUM(tblCountyCalc[Gap])
A12: State RAG (from Utilization) | B12: =IF(B6>=Inputs_State!$B$4,"RED",IF(B6>=Inputs_State!$B$3,"AMBER","GREEN"))

Sheet County_Dashboard
A1: County Dashboard (ACASM v1)
A3: Select County: | B3: Aitkin | D3: Arrivals by Category (Selected County)
A5: Arrival Points (AP) | B5: =IFERROR(INDEX(tblCountyCalc[AP],MATCH($B$3,tblCountyCalc[County],0)),"") | D5: Category | E5: Points
A6: Complexity Pressure (CPF) | B6: =IFERROR(INDEX(tblCountyCalc[CPF],MATCH($B$3,tblCountyCalc[County],0)),"") | D6: Standard Case Work | E6: =SUMIFS(tblArrivals[Points],tblArrivals[County],$B$3,tblArrivals[Category],D6)
A7: Effective Productivity (P_eff) | B7: =IFERROR(INDEX(tblCountyCalc[P_eff],MATCH($B$3,tblCountyCalc[County],0)),"") | D7: Full Locate / Long Locate | E7: =SUMIFS(tblArrivals[Points],tblArrivals[County],$B$3,tblArrivals[Category],D7)
A8: FTE On | B8: =IFERROR(INDEX(tblCountyCalc[FTE_on],MATCH($B$3,tblCountyCalc[County],0)),"") | D8: METS / Interstate Complexity | E8: =SUMIFS(tblArrivals[Points],tblArrivals[County],$B$3,tblArrivals[Category],D8)
A9: Utilization | B9: =IFERROR(INDEX(tblCountyCalc[Utilization],MATCH($B$3,tblCountyCalc[County],0)),"") | D9: Enforcement / R&M Actions | E9: =SUMIFS(tblArrivals[Points],tblArrivals[County],$B$3,tblArrivals[Category],D9)
A10: Backlog Start | B10: =IFERROR(INDEX(tblCountyCalc[Backlog_Start],MATCH($B$3,tblCountyCalc[County],0)),"") | D10: Customer Contacts - Telephone | E10: =SUMIFS(tblArrivals[Points],tblArrivals[County],$B$3,tblArrivals[Category],D10)
A11: Backlog End | B11: =IFERROR(INDEX(tblCountyCalc[Backlog_End],MATCH($B$3,tblCountyCalc[County],0)),"") | D11: Customer Contacts - Email/Portal | E11: =SUMIFS(tblArrivals[Points],tblArrivals[County],$B$3,tblArrivals[Category],D11)
A12: FTE Required | B12: =IFERROR(INDEX(tblCountyCalc[FTE_required],MATCH($B$3,tblCountyCalc[County],0)),"") | D12: Interpreter/Language Services | E12: =SUMIFS(tblArrivals[Points],tblArrivals[County],$B$3,tblArrivals[Category],D12)
A13: Staffing Gap | B13: =IFERROR(INDEX(tblCountyCalc[Gap],MATCH($B$3,tblCountyCalc[County],0)),"") | D13: Safety / High Risk Handling | E13: =SUMIFS(tblArrivals[Points],tblArrivals[County],$B$3,tblArrivals[Category],D13)
A14: RAG Status | B14: =IFERROR(INDEX(tblCountyCalc[RAG],MATCH($B$3,tblCountyCalc[County],0)),"") | D14: Incarceration Coordination | E14: =SUMIFS(tblArrivals[Points],tblArrivals[County],$B$3,tblArrivals[Category],D14)
D15: Unlocatable / Skip Work | E15: =SUMIFS(tblArrivals[Points],tblArrivals[County],$B$3,tblArrivals[Category],D15)

Sheet State_Dashboard
A1: State of Minnesota — ACASM Dashboard (ACASM v1)
A3: Period | B3: =State_Rollup!B3 | D3: Trend (fill History tab quarterly)
A4: Total Arrival Points (AP_state) | B4: =State_Rollup!B4
A5: Total Effective Capacity | B5: =State_Rollup!B5
A6: State Utilization | B6: =State_Rollup!B6
A7: Total Backlog Start | B7: =State_Rollup!B7
A8: Total Backlog End | B8: =State_Rollup!B8
A9: Total FTE Required | B9: =State_Rollup!B9
A10: Total FTE On | B10: =State_Rollup!B10
A11: Total Staffing Gap | B11: =State_Rollup!B11
A12: State RAG Status | B12: =State_Rollup!B12

Sheet Tableau_Export
A1: County Metrics (one row per county/period)
A2: County | B2: Period | C2: AP | D2: CPF | E2: P_ref | F2: P_eff | G2: FTE_on | H2: Utilization | I2: Backlog_Start | J2: Backlog_End | K2: FTE_required | L2: Gap | M2: RAG
A3: Aitkin | B3: =Inputs_State!$B$1 | C3: =IFERROR(INDEX(tblCountyCalc[AP],MATCH($A3,tblCountyCalc[County],0)),"") | D3: =IFERROR(INDEX(tblCountyCalc[CPF],MATCH($A3,tblCountyCalc[County],0)),"") | E3: =IFERROR(INDEX(tblCountyCalc[P_ref],MATCH($A3,tblCountyCalc[County],0)),"") | F3: =IFERROR(INDEX(tblCountyCalc[P_eff],MATCH($A3,tblCountyCalc[County],0)),"") | G3: =IFERROR(INDEX(tblCountyCalc[FTE_on],MATCH($A3,tblCountyCalc[County],0)),"") | H3: =IFERROR(INDEX(tblCountyCalc[Utilization],MATCH($A3,tblCountyCalc[County],0)),"") | I3: =IFERROR(INDEX(tblCountyCalc[Backlog_Start],MATCH($A3,tblCountyCalc[County],0)),"") | J3: =IFERROR(INDEX(tblCountyCalc[Backlog_End],MATCH($A3,tblCountyCalc[County],0)),"") | K3: =IFERROR(INDEX(tblCountyCalc[FTE_required],MATCH($A3,tblCountyCalc[County],0)),"") | L3: =IFERROR(INDEX(tblCountyCalc[Gap],MATCH($A3,tblCountyCalc[County],0)),"") | M3: =IFERROR(INDEX(tblCountyCalc[RAG],MATCH($A3,tblCountyCalc[County],0)),"")
A4: Anoka | B4: =Inputs_State!$B$1 | C4: =IFERROR(INDEX(tblCountyCalc[AP],MATCH($A4,tblCountyCalc[County],0)),"") | D4: =IFERROR(INDEX(tblCountyCalc[CPF],MATCH($A4,tblCountyCalc[County],0)),"") | E4: =IFERROR(INDEX(tblCountyCalc[P_ref],MATCH($A4,tblCountyCalc[County],0)),"") | F4: =IFERROR(INDEX(tblCountyCalc[P_eff],MATCH($A4,tblCountyCalc[County],0)),"") | G4: =IFERROR(INDEX(tblCountyCalc[FTE_on],MATCH($A4,tblCountyCalc[County],0)),"") | H4: =IFERROR(INDEX(tblCountyCalc[Utilization],MATCH($A4,tblCountyCalc[County],0)),"") | I4: =IFERROR(INDEX(tblCountyCalc[Backlog_Start],MATCH($A4,tblCountyCalc[County],0)),"") | J4: =IFERROR(INDEX(tblCountyCalc[Backlog_End],MATCH($A4,tblCountyCalc[County],0)),"") | K4: =IFERROR(INDEX(tblCountyCalc[FTE_required],MATCH($A4,tblCountyCalc[County],0)),"") | L4: =IFERROR(INDEX(tblCountyCalc[Gap],MATCH($A4,tblCountyCalc[County],0)),"") | M4: =IFERROR(INDEX(tblCountyCalc[RAG],MATCH($A4,tblCountyCalc[County],0)),"")
A5: Becker | B5: =Inputs_State!$B$1 | C5: =IFERROR(INDEX(tblCountyCalc[AP],MATCH($A5,tblCountyCalc[County],0)),"") | D5: =IFERROR(INDEX(tblCountyCalc[CPF],MATCH($A5,tblCountyCalc[County],0)),"") | E5: =IFERROR(INDEX(tblCountyCalc[P_ref],MATCH($A5,tblCountyCalc[County],0)),"") | F5: =IFERROR(INDEX(tblCountyCalc[P_eff],MATCH($A5,tblCountyCalc[County],0)),"") | G5: =IFERROR(INDEX(tblCountyCalc[FTE_on],MATCH($A5,tblCountyCalc[County],0)),"") | H5: =IFERROR(INDEX(tblCountyCalc[Utilization],MATCH($A5,tblCountyCalc[County],0)),"") | I5: =IFERROR(INDEX(tblCountyCalc[Backlog_Start],MATCH($A5,tblCountyCalc[County],0)),"") | J5: =IFERROR(INDEX(tblCountyCalc[Backlog_End],MATCH($A5,tblCountyCalc[County],0)),"") | K5: =IFERROR(INDEX(tblCountyCalc[FTE_required],MATCH($A5,tblCountyCalc[County],0)),"") | L5: =IFERROR(INDEX(tblCountyCalc[Gap],MATCH($A5,tblCountyCalc[County],0)),"") | M5: =IFERROR(INDEX(tblCountyCalc[RAG],MATCH($A5,tblCountyCalc[County],0)),"")
A6: Beltrami | B6: =Inputs_State!$B$1 | C6: =IFERROR(INDEX(tblCountyCalc[AP],MATCH($A6,tblCountyCalc[County],0)),"") | D6: =IFERROR(INDEX(tblCountyCalc[CPF],MATCH($A6,tblCountyCalc[County],0)),"") | E6: =IFERROR(INDEX(tblCountyCalc[P_ref],MATCH($A6,tblCountyCalc[County],0)),"") | F6: =IFERROR(INDEX(tblCountyCalc[P_eff],MATCH($A6,tblCountyCalc[County],0)),"") | G6: =IFERROR(INDEX(tblCountyCalc[FTE_on],MATCH($A6,tblCountyCalc[County],0)),"") | H6: =IFERROR(INDEX(tblCountyCalc[Utilization],MATCH($A6,tblCountyCalc[County],0)),"") | I6: =IFERROR(INDEX(tblCountyCalc[Backlog_Start],MATCH($A6,tblCountyCalc[County],0)),"") | J6: =IFERROR(INDEX(tblCountyCalc[Backlog_End],MATCH($A6,tblCountyCalc[County],0)),"") | K6: =IFERROR(INDEX(tblCountyCalc[FTE_required],MATCH($A6,tblCountyCalc[County],0)),"") | L6: =IFERROR(INDEX(tblCountyCalc[Gap],MATCH($A6,tblCountyCalc[County],0)),"") | M6: =IFERROR(INDEX(tblCountyCalc[RAG],MATCH($A6,tblCountyCalc[County],0)),"")
A7: Benton | B7: =Inputs_State!$B$1 | C7: =IFERROR(INDEX(tblCountyCalc[AP],MATCH($A7,tblCountyCalc[County],0)),"") | D7: =IFERROR(INDEX(tblCountyCalc[CPF],MATCH($A7,tblCountyCalc[County],0)),"") | E7: =IFERROR(INDEX(tblCountyCalc[P_ref],MATCH($A7,tblCountyCalc[County],0)),"") | F7: =IFERROR(INDEX(tblCountyCalc[P_eff],MATCH($A7,tblCountyCalc[County],0)),"") | G7: =IFERROR(INDEX(tblCountyCalc[FTE_on],MATCH($A7,tblCountyCalc[County],0)),"") | H7: =IFERROR(INDEX(tblCountyCalc[Utilization],MATCH($A7,tblCountyCalc[County],0)),"") | I7: =IFERROR(INDEX(tblCountyCalc[Backlog_Start],MATCH($A7,tblCountyCalc[County],0)),"") | J7: =IFERROR(INDEX(tblCountyCalc[Backlog_End],MATCH($A7,tblCountyCalc[County],0)),"") | K7: =IFERROR(INDEX(tblCountyCalc[FTE_required],MATCH($A7,tblCountyCalc[County],0)),"") | L7: =IFERROR(INDEX(tblCountyCalc[Gap],MATCH($A7,tblCountyCalc[County],0)),"") | M7: =IFERROR(INDEX(tblCountyCalc[RAG],MATCH($A7,tblCountyCalc[County],0)),"")
A8: Big Stone | B8: =Inputs_State!$B$1 | C8: =IFERROR(INDEX(tblCountyCalc[AP],MATCH($A8,tblCountyCalc[County],0)),"") | D8: =IFERROR(INDEX(tblCountyCalc[CPF],MATCH($A8,tblCountyCalc[County],0)),"") | E8: =IFERROR(INDEX(tblCountyCalc[P_ref],MATCH($A8,tblCountyCalc[County],0)),"") | F8: =IFERROR(INDEX(tblCountyCalc[P_eff],MATCH($A8,tblCountyCalc[County],0)),"") | G8: =IFERROR(INDEX(tblCountyCalc[FTE_on],MATCH($A8,tblCountyCalc[County],0)),"") | H8: =IFERROR(INDEX(tblCountyCalc[Utilization],MATCH($A8,tblCountyCalc[County],0)),"") | I8: =IFERROR(INDEX(tblCountyCalc[Backlog_Start],MATCH($A8,tblCountyCalc[County],0)),"") | J8: =IFERROR(INDEX(tblCountyCalc[Backlog_End],MATCH($A8,tblCountyCalc[County],0)),"") | K8: =IFERROR(INDEX(tblCountyCalc[FTE_required],MATCH($A8,tblCountyCalc[County],0)),"") | L8: =IFERROR(INDEX(tblCountyCalc[Gap],MATCH($A8,tblCountyCalc[County],0)),"") | M8: =IFERROR(INDEX(tblCountyCalc[RAG],MATCH($A8,tblCountyCalc[County],0)),"")
A9: Blue Earth | B9: =Inputs_State!$B$1 | C9: =IFERROR(INDEX(tblCountyCalc[AP],MATCH($A9,tblCountyCalc[County],0)),"") | D9: =IFERROR(INDEX(tblCountyCalc[CPF],MATCH($A9,tblCountyCalc[County],0)),"") | E9: =IFERROR(INDEX(tblCountyCalc[P_ref],MATCH($A9,tblCountyCalc[County],0)),"") | F9: =IFERROR(INDEX(tblCountyCalc[P_eff],MATCH($A9,tblCountyCalc[County],0)),"") | G9: =IFERROR(INDEX(tblCountyCalc[FTE_on],MATCH($A9,tblCountyCalc[County],0)),"") | H9: =IFERROR(INDEX(tblCountyCalc[Utilization],MATCH($A9,tblCountyCalc[County],0)),"") | I9: =IFERROR(INDEX(tblCountyCalc[Backlog_Start],MATCH($A9,tblCountyCalc[County],0)),"") | J9: =IFERROR(INDEX(tblCountyCalc[Backlog_End],MATCH($A9,tblCountyCalc[County],0)),"") | K9: =IFERROR(INDEX(tblCountyCalc[FTE_required],MATCH($A9,tblCountyCalc[County],0)),"") | L9: =IFERROR(INDEX(tblCountyCalc[Gap],MATCH($A9,tblCountyCalc[County],0)),"") | M9: =IFERROR(INDEX(tblCountyCalc[RAG],MATCH($A9,tblCountyCalc[County],0)),"")
A10: Brown | B10: =Inputs_State!$B$1 | C10: =IFERROR(INDEX(tblCountyCalc[AP],MATCH($A10,tblCountyCalc[County],0)),"") | D10: =IFERROR(INDEX(tblCountyCalc[CPF],MATCH($A10,tblCountyCalc[County],0)),"") | E10: =IFERROR(INDEX(tblCountyCalc[P_ref],MATCH($A10,tblCountyCalc[County],0)),"") | F10: =IFERROR(INDEX(tblCountyCalc[P_eff],MATCH($A10,tblCountyCalc[County],0)),"") | G10: =IFERROR(INDEX(tblCountyCalc[FTE_on],MATCH($A10,tblCountyCalc[County],0)),"") | H10: =IFERROR(INDEX(tblCountyCalc[Utilization],MATCH($A10,tblCountyCalc[County],0)),"") | I10: =IFERROR(INDEX(tblCountyCalc[Backlog_Start],MATCH($A10,tblCountyCalc[County],0)),"") | J10: =IFERROR(INDEX(tblCountyCalc[Backlog_End],MATCH($A10,tblCountyCalc[County],0)),"") | K10: =IFERROR(INDEX(tblCountyCalc[FTE_required],MATCH($A10,tblCountyCalc[County],0)),"") | L10: =IFERROR(INDEX(tblCountyCalc[Gap],MATCH($A10,tblCountyCalc[County],0)),"") | M10: =IFERROR(INDEX(tblCountyCalc[RAG],MATCH($A10,tblCountyCalc[County],0)),"")
A11: Carlton | B11: =Inputs_State!$B$1 | C11: =IFERROR(INDEX(tblCountyCalc[AP],MATCH($A11,tblCountyCalc[County],0)),"") | D11: =IFERROR(INDEX(tblCountyCalc[CPF],MATCH($A11,tblCountyCalc[County],0)),"") | E11: =IFERROR(INDEX(tblCountyCalc[P_ref],MATCH($A11,tblCountyCalc[County],0)),"") | F11: =IFERROR(INDEX(tblCountyCalc[P_eff],MATCH($A11,tblCountyCalc[County],0)),"") | G11: =IFERROR(INDEX(tblCountyCalc[FTE_on],MATCH($A11,tblCountyCalc[County],0)),"") | H11: =IFERROR(INDEX(tblCountyCalc[Utilization],MATCH($A11,tblCountyCalc[County],0)),"") | I11: =IFERROR(INDEX(tblCountyCalc[Backlog_Start],MATCH($A11,tblCountyCalc[County],0)),"") | J11: =IFERROR(INDEX(tblCountyCalc[Backlog_End],MATCH($A11,tblCountyCalc[County],0)),"") | K11: =IFERROR(INDEX(tblCountyCalc[FTE_required],MATCH($A11,tblCountyCalc[County],0)),"") | L11: =IFERROR(INDEX(tblCountyCalc[Gap],MATCH($A11,tblCountyCalc[County],0)),"") | M11: =IFERROR(INDEX(tblCountyCalc[RAG],MATCH($A11,tblCountyCalc[County],0)),"")
A12: Carver | B12: =Inputs_State!$B$1 | C12: =IFERROR(INDEX(tblCountyCalc[AP],MATCH($A12,tblCountyCalc[County],0)),"") | D12: =IFERROR(INDEX(tblCountyCalc[CPF],MATCH($A12,tblCountyCalc[County],0)),"") | E12: =IFERROR(INDEX(tblCountyCalc[P_ref],MATCH($A12,tblCountyCalc[County],0)),"") | F12: =IFERROR(INDEX(tblCountyCalc[P_eff],MATCH($A12,tblCountyCalc[County],0)),"") | G12: =IFERROR(INDEX(tblCountyCalc[FTE_on],MATCH($A12,tblCountyCalc[County],0)),"") | H12: =IFERROR(INDEX(tblCountyCalc[Utilization],MATCH($A12,tblCountyCalc[County],0)),"") | I12: =IFERROR(INDEX(tblCountyCalc[Backlog_Start],MATCH($A12,tblCountyCalc[County],0)),"") | J12: =IFERROR(INDEX(tblCountyCalc[Backlog_End],MATCH($A12,tblCountyCalc[County],0)),"") | K12: =IFERROR(INDEX(tblCountyCalc[FTE_required],MATCH($A12,tblCountyCalc[County],0)),"") | L12: =IFERROR(INDEX(tblCountyCalc[Gap],MATCH($A12,tblCountyCalc[County],0)),"") | M12: =IFERROR(INDEX(tblCountyCalc[RAG],MATCH($A12,tblCountyCalc[County],0)),"")
A13: Cass | B13: =Inputs_State!$B$1 | C13: =IFERROR(INDEX(tblCountyCalc[AP],MATCH($A13,tblCountyCalc[County],0)),"") | D13: =IFERROR(INDEX(tblCountyCalc[CPF],MATCH($A13,tblCountyCalc[County],0)),"") | E13: =IFERROR(INDEX(tblCountyCalc[P_ref],MATCH($A13,tblCountyCalc[County],0)),"") | F13: =IFERROR(INDEX(tblCountyCalc[P_eff],MATCH($A13,tblCountyCalc[County],0)),"") | G13: =IFERROR(INDEX(tblCountyCalc[FTE_on],MATCH($A13,tblCountyCalc[County],0)),"") | H13: =IFERROR(INDEX(tblCountyCalc[Utilization],MATCH($A13,tblCountyCalc[County],0)),"") | I13: =IFERROR(INDEX(tblCountyCalc[Backlog_Start],MATCH($A13,tblCountyCalc[County],0)),"") | J13: =IFERROR(INDEX(tblCountyCalc[Backlog_End],MATCH($A13,tblCountyCalc[County],0)),"") | K13: =IFERROR(INDEX(tblCountyCalc[FTE_required],MATCH($A13,tblCountyCalc[County],0)),"") | L13: =IFERROR(INDEX(tblCountyCalc[Gap],MATCH($A13,tblCountyCalc[County],0)),"") | M13: =IFERROR(INDEX(tblCountyCalc[RAG],MATCH($A13,tblCountyCalc[County],0)),"")
A14: Chippewa | B14: =Inputs_State!$B$1 | C14: =IFERROR(INDEX(tblCountyCalc[AP],MATCH($A14,tblCountyCalc[County],0)),"") | D14: =IFERROR(INDEX(tblCountyCalc[CPF],MATCH($A14,tblCountyCalc[County],0)),"") | E14: =IFERROR(INDEX(tblCountyCalc[P_ref],MATCH($A14,tblCountyCalc[County],0)),"") | F14: =IFERROR(INDEX(tblCountyCalc[P_eff],MATCH($A14,tblCountyCalc[County],0)),"") | G14: =IFERROR(INDEX(tblCountyCalc[FTE_on],MATCH($A14,tblCountyCalc[County],0)),"") | H14: =IFERROR(INDEX(tblCountyCalc[Utilization],MATCH($A14,tblCountyCalc[County],0)),"") | I14: =IFERROR(INDEX(tblCountyCalc[Backlog_Start],MATCH($A14,tblCountyCalc[County],0)),"") | J14: =IFERROR(INDEX(tblCountyCalc[Backlog_End],MATCH($A14,tblCountyCalc[County],0)),"") | K14: =IFERROR(INDEX(tblCountyCalc[FTE_required],MATCH($A14,tblCountyCalc[County],0)),"") | L14: =IFERROR(INDEX(tblCountyCalc[Gap],MATCH($A14,tblCountyCalc[County],0)),"") | M14: =IFERROR(INDEX(tblCountyCalc[RAG],MATCH($A14,tblCountyCalc[County],0)),"")
... A88: Yellow Medicine | B88: =Inputs_State!$B$1 | C88: =IFERROR(INDEX(tblCountyCalc[AP],MATCH($A88,tblCountyCalc[County],0)),"") | D88: =IFERROR(INDEX(tblCountyCalc[CPF],MATCH($A88,tblCountyCalc[County],0)),"") | E88: =IFERROR(INDEX(tblCountyCalc[P_ref],MATCH($A88,tblCountyCalc[County],0)),"") | F88: =IFERROR(INDEX(tblCountyCalc[P_eff],MATCH($A88,tblCountyCalc[County],0)),"") | G88: =IFERROR(INDEX(tblCountyCalc[FTE_on],MATCH($A88,tblCountyCalc[County],0)),"") | H88: =IFERROR(INDEX(tblCountyCalc[Utilization],MATCH($A88,tblCountyCalc[County],0)),"") | I88: =IFERROR(INDEX(tblCountyCalc[Backlog_Start],MATCH($A88,tblCountyCalc[County],0)),"") | J88: =IFERROR(INDEX(tblCountyCalc[Backlog_End],MATCH($A88,tblCountyCalc[County],0)),"") | K88: =IFERROR(INDEX(tblCountyCalc[FTE_required],MATCH($A88,tblCountyCalc[County],0)),"") | L88: =IFERROR(INDEX(tblCountyCalc[Gap],MATCH($A88,tblCountyCalc[County],0)),"") | M88: =IFERROR(INDEX(tblCountyCalc[RAG],MATCH($A88,tblCountyCalc[County],0)),"")

Sheet History
A1: History (paste quarterly snapshots here for trends / Tableau)
A2: Period | B2: County | C2: AP | D2: Utilization | E2: Backlog_End | F2: FTE_required | G2: Gap | H2: RAG
